0: command not found
-bash: */2: No such file or directory
Traceback (most recent call last):
  File "/mnt/d/haseeb/venv/lib/python3.10/site-packages/mysql/connector/connection_cext.py", line 291, in _open_connection
    self._cmysql.connect(**cnx_kwargs)
_mysql_connector.MySQLInterfaceError: Can't connect to MySQL server on 'localhost:3306' (111)

The above exception was the direct cause of the following exception:

Traceback (most recent call last):
  File "/mnt/d/haseeb/main.py", line 126, in <module>
    conn = db_config.connect()
  File "/mnt/d/haseeb/database_config.py", line 23, in connect
    conn = mysql.connector.connect(
  File "/mnt/d/haseeb/venv/lib/python3.10/site-packages/mysql/connector/pooling.py", line 293, in connect
    return CMySQLConnection(*args, **kwargs)
  File "/mnt/d/haseeb/venv/lib/python3.10/site-packages/mysql/connector/connection_cext.py", line 120, in __init__
    self.connect(**kwargs)
  File "/mnt/d/haseeb/venv/lib/python3.10/site-packages/mysql/connector/abstracts.py", line 1181, in connect
    self._open_connection()
  File "/mnt/d/haseeb/venv/lib/python3.10/site-packages/mysql/connector/connection_cext.py", line 296, in _open_connection
    raise get_mysql_exception(
mysql.connector.errors.DatabaseError: 2003 (HY000): Can't connect to MySQL server on 'localhost:3306' (111)
Traceback (most recent call last):
  File "/mnt/d/haseeb/venv/lib/python3.10/site-packages/mysql/connector/connection_cext.py", line 291, in _open_connection
    self._cmysql.connect(**cnx_kwargs)
_mysql_connector.MySQLInterfaceError: Can't connect to MySQL server on 'localhost:3306' (111)

The above exception was the direct cause of the following exception:

Traceback (most recent call last):
  File "/mnt/d/haseeb/main.py", line 126, in <module>
    conn = db_config.connect()
  File "/mnt/d/haseeb/database_config.py", line 23, in connect
    conn = mysql.connector.connect(
  File "/mnt/d/haseeb/venv/lib/python3.10/site-packages/mysql/connector/pooling.py", line 293, in connect
    return CMySQLConnection(*args, **kwargs)
  File "/mnt/d/haseeb/venv/lib/python3.10/site-packages/mysql/connector/connection_cext.py", line 120, in __init__
    self.connect(**kwargs)
  File "/mnt/d/haseeb/venv/lib/python3.10/site-packages/mysql/connector/abstracts.py", line 1181, in connect
    self._open_connection()
  File "/mnt/d/haseeb/venv/lib/python3.10/site-packages/mysql/connector/connection_cext.py", line 296, in _open_connection
    raise get_mysql_exception(
mysql.connector.errors.DatabaseError: 2003 (HY000): Can't connect to MySQL server on 'localhost:3306' (111)
Traceback (most recent call last):
  File "/mnt/d/haseeb/venv/lib/python3.10/site-packages/mysql/connector/connection_cext.py", line 291, in _open_connection
    self._cmysql.connect(**cnx_kwargs)
_mysql_connector.MySQLInterfaceError: Can't connect to MySQL server on 'localhost:3306' (111)

The above exception was the direct cause of the following exception:

Traceback (most recent call last):
  File "/mnt/d/haseeb/main.py", line 126, in <module>
    conn = db_config.connect()
  File "/mnt/d/haseeb/database_config.py", line 23, in connect
    conn = mysql.connector.connect(
  File "/mnt/d/haseeb/venv/lib/python3.10/site-packages/mysql/connector/pooling.py", line 293, in connect
    return CMySQLConnection(*args, **kwargs)
  File "/mnt/d/haseeb/venv/lib/python3.10/site-packages/mysql/connector/connection_cext.py", line 120, in __init__
    self.connect(**kwargs)
  File "/mnt/d/haseeb/venv/lib/python3.10/site-packages/mysql/connector/abstracts.py", line 1181, in connect
    self._open_connection()
  File "/mnt/d/haseeb/venv/lib/python3.10/site-packages/mysql/connector/connection_cext.py", line 296, in _open_connection
    raise get_mysql_exception(
mysql.connector.errors.DatabaseError: 2003 (HY000): Can't connect to MySQL server on 'localhost:3306' (111)
Traceback (most recent call last):
  File "/mnt/d/haseeb/venv/lib/python3.10/site-packages/mysql/connector/connection_cext.py", line 291, in _open_connection
    self._cmysql.connect(**cnx_kwargs)
_mysql_connector.MySQLInterfaceError: Can't connect to MySQL server on 'localhost:3306' (111)

The above exception was the direct cause of the following exception:

Traceback (most recent call last):
  File "/mnt/d/haseeb/main.py", line 126, in <module>
    conn = db_config.connect()
  File "/mnt/d/haseeb/database_config.py", line 23, in connect
    conn = mysql.connector.connect(
  File "/mnt/d/haseeb/venv/lib/python3.10/site-packages/mysql/connector/pooling.py", line 293, in connect
    return CMySQLConnection(*args, **kwargs)
  File "/mnt/d/haseeb/venv/lib/python3.10/site-packages/mysql/connector/connection_cext.py", line 120, in __init__
    self.connect(**kwargs)
  File "/mnt/d/haseeb/venv/lib/python3.10/site-packages/mysql/connector/abstracts.py", line 1181, in connect
    self._open_connection()
  File "/mnt/d/haseeb/venv/lib/python3.10/site-packages/mysql/connector/connection_cext.py", line 296, in _open_connection
    raise get_mysql_exception(
mysql.connector.errors.DatabaseError: 2003 (HY000): Can't connect to MySQL server on 'localhost:3306' (111)
